Workbook

Sheet DATA
H1: Q1 2024
H2: Q2 2024
H3: Q3 2024
H4: Q4 2024
E5: Q1 2024
C8: Q1
C9: October | D9: November | E9: December | F9: October | G9: November | H9: December | I9: October | J9: November | K9: December | L9: October | M9: November | N9: December | O9: October | P9: November | Q9: December | R9: October | S9: November | T9: December | U9: October | V9: November | W9: December | X9: October | Y9: November | Z9: December | AA9: October | AB9: November | AC9: December | AD9: October | AE9: November | AF9: December | AG9: October | AH9: November | AI9: December | AJ9: October | AK9: November | AL9: December | AM9: October | AN9: November | AO9: December | AP9: October | AQ9: November | AR9: December
C10: Revenue | D10: Revenue | E10: Revenue | F10: Target Revenue | G10: Target Revenue | H10: Target Revenue | I10: Previous Year Revenue | J10: Previous Year Revenue | K10: Previous Year Revenue | L10: Number of Customers | M10: Number of Customers | N10: Number of Customers | O10: Number of New Customers Target | P10: Number of New Customers Target | Q10: Number of New Customers Target | R10: Number of New Customers | S10: Number of New Customers | T10: Number of New Customers | U10: Number of New Customers Previous Year | V10: Number of New Customers Previous Year | W10: Number of New Customers Previous Year | X10: Customer Acquisition Costs | Y10: Customer Acquisition Costs | Z10: Customer Acquisition Costs | AA10: Customer AC (per customer) | AB10: Customer AC (per customer) | AC10: Customer AC (per customer) | AD10: Customer AC (per customer) Target | AE10: Customer AC (per customer) Target | AF10: Customer AC (per customer) Target | AG10: Customer Aquis. Costs (per customer) PY | AH10: Customer Aquis. Costs (per customer) PY | AI10: Customer Aquis. Costs (per customer) PY | AJ10: Revenue per Customer | AK10: Revenue per Customer | AL10: Revenue per Customer | AM10: Revenue per Customer PY | AN10: Revenue per Customer PY | AO10: Revenue per Customer PY | AP10: Target Revenue per Customer | AQ10: Target Revenue per Customer | AR10: Target Revenue per Customer
B11: Jacob | C11: {=_xlfn.SWITCH($E$5,$H$1,C28,$H$2,C40,$H$3,C52,$H$4,C64)} -> 135000 | D11: {=_xlfn.SWITCH($E$5,$H$1,D28,$H$2,D40,$H$3,D52,$H$4,D64)} -> 130000 | E11: {=_xlfn.SWITCH($E$5,$H$1,E28,$H$2,E40,$H$3,E52,$H$4,E64)} -> 160000 | F11: {=_xlfn.SWITCH($E$5,$H$1,F28,$H$2,F40,$H$3,F52,$H$4,F64)} -> 150000 | G11: {=_xlfn.SWITCH($E$5,$H$1,G28,$H$2,G40,$H$3,G52,$H$4,G64)} -> 140000 | H11: {=_xlfn.SWITCH($E$5,$H$1,H28,$H$2,H40,$H$3,H52,$H$4,H64)} -> 150000 | I11: {=_xlfn.SWITCH($E$5,$H$1,I28,$H$2,I40,$H$3,I52,$H$4,I64)} -> 115000 | J11: {=_xlfn.SWITCH($E$5,$H$1,J28,$H$2,J40,$H$3,J52,$H$4,J64)} -> 140000 | ... AR11: {=_xlfn.SWITCH($E$5,$H$1,AR28,$H$2,AR40,$H$3,AR52,$H$4,AR64)} -> 2400
B12: Arnold | C12: {=_xlfn.SWITCH($E$5,$H$1,C29,$H$2,C41,$H$3,C53,$H$4,C65)} -> 170000 | D12: {=_xlfn.SWITCH($E$5,$H$1,D29,$H$2,D41,$H$3,D53,$H$4,D65)} -> 160000 | E12: {=_xlfn.SWITCH($E$5,$H$1,E29,$H$2,E41,$H$3,E53,$H$4,E65)} -> 185000 | F12: {=_xlfn.SWITCH($E$5,$H$1,F29,$H$2,F41,$H$3,F53,$H$4,F65)} -> 150000 | G12: {=_xlfn.SWITCH($E$5,$H$1,G29,$H$2,G41,$H$3,G53,$H$4,G65)} -> 140000 | H12: {=_xlfn.SWITCH($E$5,$H$1,H29,$H$2,H41,$H$3,H53,$H$4,H65)} -> 150000 | I12: {=_xlfn.SWITCH($E$5,$H$1,I29,$H$2,I41,$H$3,I53,$H$4,I65)} -> 160000 | J12: {=_xlfn.SWITCH($E$5,$H$1,J29,$H$2,J41,$H$3,J53,$H$4,J65)} -> 130000 | ... AR12: {=_xlfn.SWITCH($E$5,$H$1,AR29,$H$2,AR41,$H$3,AR53,$H$4,AR65)} -> 2400
B13: Naomi | C13: {=_xlfn.SWITCH($E$5,$H$1,C30,$H$2,C42,$H$3,C54,$H$4,C66)} -> 175000 | D13: {=_xlfn.SWITCH($E$5,$H$1,D30,$H$2,D42,$H$3,D54,$H$4,D66)} -> 135000 | E13: {=_xlfn.SWITCH($E$5,$H$1,E30,$H$2,E42,$H$3,E54,$H$4,E66)} -> 145000 | F13: {=_xlfn.SWITCH($E$5,$H$1,F30,$H$2,F42,$H$3,F54,$H$4,F66)} -> 150000 | G13: {=_xlfn.SWITCH($E$5,$H$1,G30,$H$2,G42,$H$3,G54,$H$4,G66)} -> 140000 | H13: {=_xlfn.SWITCH($E$5,$H$1,H30,$H$2,H42,$H$3,H54,$H$4,H66)} -> 150000 | I13: {=_xlfn.SWITCH($E$5,$H$1,I30,$H$2,I42,$H$3,I54,$H$4,I66)} -> 170000 | J13: {=_xlfn.SWITCH($E$5,$H$1,J30,$H$2,J42,$H$3,J54,$H$4,J66)} -> 145000 | ... AR13: {=_xlfn.SWITCH($E$5,$H$1,AR30,$H$2,AR42,$H$3,AR54,$H$4,AR66)} -> 2400
B14: David | C14: {=_xlfn.SWITCH($E$5,$H$1,C31,$H$2,C43,$H$3,C55,$H$4,C67)} -> 156000 | D14: {=_xlfn.SWITCH($E$5,$H$1,D31,$H$2,D43,$H$3,D55,$H$4,D67)} -> 175000 | E14: {=_xlfn.SWITCH($E$5,$H$1,E31,$H$2,E43,$H$3,E55,$H$4,E67)} -> 155000 | F14: {=_xlfn.SWITCH($E$5,$H$1,F31,$H$2,F43,$H$3,F55,$H$4,F67)} -> 150000 | G14: {=_xlfn.SWITCH($E$5,$H$1,G31,$H$2,G43,$H$3,G55,$H$4,G67)} -> 140000 | H14: {=_xlfn.SWITCH($E$5,$H$1,H31,$H$2,H43,$H$3,H55,$H$4,H67)} -> 150000 | I14: {=_xlfn.SWITCH($E$5,$H$1,I31,$H$2,I43,$H$3,I55,$H$4,I67)} -> 165000 | J14: {=_xlfn.SWITCH($E$5,$H$1,J31,$H$2,J43,$H$3,J55,$H$4,J67)} -> 155000 | ... AR14: {=_xlfn.SWITCH($E$5,$H$1,AR31,$H$2,AR43,$H$3,AR55,$H$4,AR67)} -> 2400
B15: Ariel | C15: {=_xlfn.SWITCH($E$5,$H$1,C32,$H$2,C44,$H$3,C56,$H$4,C68)} -> 135500 | D15: {=_xlfn.SWITCH($E$5,$H$1,D32,$H$2,D44,$H$3,D56,$H$4,D68)} -> 190000 | E15: {=_xlfn.SWITCH($E$5,$H$1,E32,$H$2,E44,$H$3,E56,$H$4,E68)} -> 140000 | F15: {=_xlfn.SWITCH($E$5,$H$1,F32,$H$2,F44,$H$3,F56,$H$4,F68)} -> 150000 | G15: {=_xlfn.SWITCH($E$5,$H$1,G32,$H$2,G44,$H$3,G56,$H$4,G68)} -> 140000 | H15: {=_xlfn.SWITCH($E$5,$H$1,H32,$H$2,H44,$H$3,H56,$H$4,H68)} -> 150000 | I15: {=_xlfn.SWITCH($E$5,$H$1,I32,$H$2,I44,$H$3,I56,$H$4,I68)} -> 155000 | J15: {=_xlfn.SWITCH($E$5,$H$1,J32,$H$2,J44,$H$3,J56,$H$4,J68)} -> 120000 | ... AR15: {=_xlfn.SWITCH($E$5,$H$1,AR32,$H$2,AR44,$H$3,AR56,$H$4,AR68)} -> 2400
B16: TOTAL | C16: =SUM(C11:C15) -> 771500 | D16: =SUM(D11:D15) -> 790000 | E16: =SUM(E11:E15) -> 785000 | F16: =SUM(F11:F15) -> 750000 | G16: =SUM(G11:G15) -> 700000 | H16: =SUM(H11:H15) -> 750000 | I16: =SUM(I11:I15) -> 765000 | J16: =SUM(J11:J15) -> 690000 | ... Z16: =SUM(Z11:Z15) -> 41800 | AA16: =AVERAGE(AA11:AA15) -> 375.894 | AB16: =AVERAGE(AB11:AB15) -> 509.438 | AC16: =AVERAGE(AC11:AC15) -> 430.074 | AD16: =AVERAGE(AD11:AD15) -> 350 | AE16: =AVERAGE(AE11:AE15) -> 350 | AF16: =AVERAGE(AF11:AF15) -> 350 | AG16: =AVERAGE(AG11:AG15) -> 377.4 | AH16: =AVERAGE(AH11:AH15) -> 354 | ... AR16: =AVERAGE(AR11:AR15) -> 2400
B19: TOTAL CUSTOMERS PER YEAR | C19: =SUM(L33:N33,L45:N45,L57:N57,L69:N69) -> 3799
B20: NEW CUSTOMERS PER YEAR | C20: =SUM(R33:T33,R45:T45,R57:T57,R69:T69) -> 1228
B21: REVENUE PER CUSTOMER | C21: =C22/C19 -> 2440.5107
B22: TOTAL REVENUE PER YEAR | C22: =SUM(C33:E33,C45:E45,C57:E57,C69:E69) -> 9271500
C25: Q1 2023
C26: January | D26: February | E26: March | F26: January | G26: February | H26: March | I26: January | J26: February | K26: March | L26: January | M26: February | N26: March | O26: January | P26: February | Q26: March | R26: January | S26: February | T26: March | U26: January | V26: February | W26: March | X26: January | Y26: February | Z26: March | AA26: January | AB26: February | AC26: March | AD26: January | AE26: February | AF26: March | AG26: January | AH26: February | AI26: March | AJ26: January | AK26: February | AL26: March | AM26: January | AN26: February | AO26: March | AP26: January | AQ26: February | AR26: March
C27: Revenue | D27: Revenue | E27: Revenue | F27: Target Revenue | G27: Target Revenue | H27: Target Revenue | I27: Previous Year Revenue | J27: Previous Year Revenue | K27: Previous Year Revenue | L27: Number of Customers | M27: Number of Customers | N27: Number of Customers | O27: Number of New Customers Target | P27: Number of New Customers Target | Q27: Number of New Customers Target | R27: Number of New Customers | S27: Number of New Customers | T27: Number of New Customers | U27: Number of New Customers Previous Year | V27: Number of New Customers Previous Year | W27: Number of New Customers Previous Year | X27: Customer Acquisition Costs | Y27: Customer Acquisition Costs | Z27: Customer Acquisition Costs | AA27: Customer AC (per customer) | AB27: Customer AC (per customer) | AC27: Customer AC (per customer) | AD27: Customer AC (per customer) Target | AE27: Customer AC (per customer) Target | AF27: Customer AC (per customer) Target | AG27: Customer Aquis. Costs (per customer) PY | AH27: Customer Aquis. Costs (per customer) PY | AI27: Customer Aquis. Costs (per customer) PY | AJ27: Revenue per Customer | AK27: Revenue per Customer | AL27: Revenue per Customer | AM27: Revenue per Customer PY | AN27: Revenue per Customer PY | AO27: Revenue per Customer PY | AP27: Target Revenue per Customer | AQ27: Target Revenue per Customer | AR27: Target Revenue per Customer
B28: Jacob | C28: 135000 | D28: 130000 | E28: 160000 | F28: 150000 | G28: 140000 | H28: 150000 | I28: 115000 | J28: 140000 | K28: 160000 | L28: 57 | M28: 58 | N28: 63 | O28: 25 | P28: 20 | Q28: 25 | R28: 10 | S28: 11 | T28: 18 | U28: 9 | V28: 12 | W28: 14 | X28: 4200 | Y28: 5000 | Z28: 5500 | AA28: 420 | AB28: 454.55 | AC28: 305.56 | AD28: 350 | AE28: 350 | AF28: 350 | AG28: 400 | AH28: 385 | AI28: 390 | AJ28: 2192.98 | AK28: 2241.38 | AL28: 2539.68 | AM28: 2200 | AN28: 2100 | AO28: 2400 | AP28: 2500 | AQ28: 2600 | AR28: 2400
B29: Arnold | C29: 170000 | D29: 160000 | E29: 185000 | F29: 150000 | G29: 140000 | H29: 150000 | I29: 160000 | J29: 130000 | K29: 125000 | L29: 74 | M29: 70 | N29: 74 | O29: 25 | P29: 20 | Q29: 25 | R29: 22 | S29: 23 | T29: 26 | U29: 17 | V29: 24 | W29: 22 | X29: 7800 | Y29: 10000 | Z29: 9000 | AA29: 354.55 | AB29: 434.78 | AC29: 346.15 | AD29: 350 | AE29: 350 | AF29: 350 | AG29: 402 | AH29: 290 | AI29: 380 | AJ29: 2432.43 | AK29: 2285.71 | AL29: 2500 | AM29: 2100 | AN29: 2200 | AO29: 2300 | AP29: 2500 | AQ29: 2600 | AR29: 2400
B30: Naomi | C30: 175000 | D30: 135000 | E30: 145000 | F30: 150000 | G30: 140000 | H30: 150000 | I30: 170000 | J30: 145000 | K30: 130000 | L30: 70 | M30: 55 | N30: 61 | O30: 25 | P30: 20 | Q30: 25 | R30: 35 | S30: 20 | T30: 17 | U30: 36 | V30: 25 | W30: 21 | X30: 13200 | Y30: 9500 | Z30: 8300 | AA30: 377.14 | AB30: 475 | AC30: 488.24 | AD30: 350 | AE30: 350 | AF30: 350 | AG30: 350 | AH30: 385 | AI30: 352 | AJ30: 2428.57 | AK30: 2454.55 | AL30: 2377.05 | AM30: 2500 | AN30: 2500 | AO30: 2300 | AP30: 2500 | AQ30: 2600 | AR30: 2400
B31: David | C31: 156000 | D31: 175000 | E31: 155000 | F31: 150000 | G31: 140000 | H31: 150000 | I31: 165000 | J31: 155000 | K31: 140000 | L31: 66 | M31: 68 | N31: 63 | O31: 25 | P31: 20 | Q31: 25 | R31: 18 | S31: 14 | T31: 24 | U31: 14 | V31: 25 | W31: 22 | X31: 6500 | Y31: 9000 | Z31: 8500 | AA31: 361.11 | AB31: 642.86 | AC31: 354.17 | AD31: 350 | AE31: 350 | AF31: 350 | AG31: 350 | AH31: 360 | AI31: 388 | AJ31: 2272.73 | AK31: 2573.53 | AL31: 2460.32 | AM31: 2200 | AN31: 2600 | AO31: 2400 | AP31: 2500 | AQ31: 2600 | AR31: 2400
B32: Ariel | C32: 135500 | D32: 190000 | E32: 140000 | F32: 150000 | G32: 140000 | H32: 150000 | I32: 155000 | J32: 120000 | K32: 150000 | L32: 71 | M32: 62 | N32: 51 | O32: 25 | P32: 20 | Q32: 25 | R32: 33 | S32: 20 | T32: 16 | U32: 20 | V32: 25 | W32: 24 | X32: 12100 | Y32: 10800 | Z32: 10500 | AA32: 366.67 | AB32: 540 | AC32: 656.25 | AD32: 350 | AE32: 350 | AF32: 350 | AG32: 385 | AH32: 350 | AI32: 406 | AJ32: 1901.41 | AK32: 3064.52 | AL32: 2745.1 | AM32: 2100 | AN32: 2800 | AO32: 2700 | AP32: 2500 | AQ32: 2600 | AR32: 2400
B33: TOTAL | C33: =SUM(C28:C32) -> 771500 | D33: =SUM(D28:D32) -> 790000 | E33: =SUM(E28:E32) -> 785000 | F33: =SUM(F28:F32) -> 750000 | G33: =SUM(G28:G32) -> 700000 | H33: =SUM(H28:H32) -> 750000 | I33: =SUM(I28:I32) -> 765000 | J33: =SUM(J28:J32) -> 690000 | ... AR33: =SUM(AR28:AR32) -> 12000
C37: Q2 2023
C38: April | D38: May | E38: June | F38: April | G38: May | H38: June | I38: April | J38: May | K38: June | L38: April | M38: May | N38: June | O38: April | P38: May | Q38: June | R38: April | S38: May | T38: June | U38: April | V38: May | W38: June | X38: April | Y38: May | Z38: June | AA38: April | AB38: May | AC38: June | AD38: April | AE38: May | AF38: June | AG38: April | AH38: May | AI38: June | AJ38: April | AK38: May | AL38: June | AM38: April | AN38: May | AO38: June | AP38: April | AQ38: May | AR38: June
C39: Revenue | D39: Revenue | E39: Revenue | F39: Target Revenue | G39: Target Revenue | H39: Target Revenue | I39: Previous Year Revenue | J39: Previous Year Revenue | K39: Previous Year Revenue | L39: Number of Customers | M39: Number of Customers | N39: Number of Customers | O39: Number of New Customers Target | P39: Number of New Customers Target | Q39: Number of New Customers Target | R39: Number of New Customers | S39: Number of New Customers | T39: Number of New Customers | U39: Number of New Customers Previous Year | V39: Number of New Customers Previous Year | W39: Number of New Customers Previous Year | X39: Customer Acquisition Costs | Y39: Customer Acquisition Costs | Z39: Customer Acquisition Costs | AA39: Customer AC (per customer) | AB39: Customer AC (per customer) | AC39: Customer AC (per customer) | AD39: Customer AC (per customer) Target | AE39: Customer AC (per customer) Target | AF39: Customer AC (per customer) Target | AG39: Customer Aquis. Costs (per customer) PY | AH39: Customer Aquis. Costs (per customer) PY | AI39: Customer Aquis. Costs (per customer) PY | AJ39: Revenue per Customer | AK39: Revenue per Customer | AL39: Revenue per Customer | AM39: Revenue per Customer PY | AN39: Revenue per Customer PY | AO39: Revenue per Customer PY | AP39: Target Revenue per Customer | AQ39: Target Revenue per Customer | AR39: Target Revenue per Customer
B40: Jacob | C40: 130000 | D40: 135000 | E40: 150000 | F40: 150000 | G40: 160000 | H40: 140000 | I40: 125000 | J40: 160000 | K40: 135000 | L40: 58 | M40: 63 | N40: 55 | O40: 30 | P40: 30 | Q40: 25 | R40: 12 | S40: 25 | T40: 11 | U40: 11 | V40: 21 | W40: 14 | X40: 5000 | Y40: 4500 | Z40: 5000 | AA40: 416.67 | AB40: 180 | AC40: 454.55 | AD40: 400 | AE40: 350 | AF40: 350 | AG40: 400 | AH40: 385 | AI40: 390 | AJ40: 2068.97 | AK40: 2142.86 | AL40: 2727.27 | AM40: 2100 | AN40: 2000 | AO40: 2600 | AP40: 2700 | AQ40: 2500 | AR40: 2600
B41: Arnold | C41: 175000 | D41: 155000 | E41: 190000 | F41: 150000 | G41: 160000 | H41: 140000 | I41: 145000 | J41: 125000 | K41: 125000 | L41: 70 | M41: 74 | N41: 65 | O41: 30 | P41: 30 | Q41: 25 | R41: 26 | S41: 18 | T41: 23 | U41: 17 | V41: 18 | W41: 15 | X41: 9800 | Y41: 9800 | Z41: 6500 | AA41: 376.92 | AB41: 544.44 | AC41: 282.61 | AD41: 400 | AE41: 350 | AF41: 350 | AG41: 402 | AH41: 290 | AI41: 380 | AJ41: 2500 | AK41: 2094.59 | AL41: 2923.08 | AM41: 2200 | AN41: 2000 | AO41: 2200 | AP41: 2700 | AQ41: 2500 | AR41: 2600
B42: Naomi | C42: 180000 | D42: 145000 | E42: 155000 | F42: 150000 | G42: 160000 | H42: 140000 | I42: 155000 | J42: 130000 | K42: 125000 | L42: 55 | M42: 61 | N42: 44 | O42: 30 | P42: 30 | Q42: 25 | R42: 31 | S42: 25 | T42: 20 | U42: 25 | V42: 21 | W42: 22 | X42: 9500 | Y42: 10200 | Z42: 8000 | AA42: 306.45 | AB42: 408 | AC42: 400 | AD42: 400 | AE42: 350 | AF42: 350 | AG42: 350 | AH42: 385 | AI42: 352 | AJ42: 3272.73 | AK42: 2377.05 | AL42: 3522.73 | AM42: 3000 | AN42: 2200 | AO42: 2100 | AP42: 2700 | AQ42: 2500 | AR42: 2600
B43: David | C43: 160000 | D43: 180000 | E43: 175000 | F43: 150000 | G43: 160000 | H43: 140000 | I43: 145000 | J43: 140000 | K43: 160000 | L43: 68 | M43: 63 | N43: 50 | O43: 30 | P43: 30 | Q43: 25 | R43: 28 | S43: 15 | T43: 14 | U43: 17 | V43: 18 | W43: 21 | X43: 9000 | Y43: 5600 | Z43: 7000 | AA43: 321.43 | AB43: 373.33 | AC43: 500 | AD43: 400 | AE43: 350 | AF43: 350 | AG43: 350 | AH43: 360 | AI43: 388 | AJ43: 2352.94 | AK43: 2857.14 | AL43: 3500 | AM43: 2200 | AN43: 2450 | AO43: 3300 | AP43: 2700 | AQ43: 2500 | AR43: 2600
B44: Ariel | C44: 205000 | D44: 195000 | E44: 125000 | F44: 150000 | G44: 160000 | H44: 140000 | I44: 125000 | J44: 150000 | K44: 145000 | L44: 62 | M44: 51 | N44: 35 | O44: 30 | P44: 30 | Q44: 25 | R44: 25 | S44: 18 | T44: 20 | U44: 20 | V44: 13 | W44: 20 | X44: 10800 | Y44: 9500 | Z44: 9000 | AA44: 432 | AB44: 527.78 | AC44: 450 | AD44: 400 | AE44: 350 | AF44: 350 | AG44: 385 | AH44: 350 | AI44: 406 | AJ44: 3306.45 | AK44: 3823.53 | AL44: 3571.43 | AM44: 2900 | AN44: 3100 | AO44: 3100 | AP44: 2700 | AQ44: 2500 | AR44: 2600
B45: TOTAL | C45: =SUM(C40:C44) -> 850000 | D45: =SUM(D40:D44) -> 810000 | E45: =SUM(E40:E44) -> 795000 | F45: =SUM(F40:F44) -> 750000 | G45: =SUM(G40:G44) -> 800000 | H45: =SUM(H40:H44) -> 700000 | I45: =SUM(I40:I44) -> 695000 | J45: =SUM(J40:J44) -> 705000 | ... AR45: =SUM(AR40:AR44) -> 13000
C49: Q3 2023
C50: July | D50: August | E50: September | F50: July | G50: August | H50: September | I50: July | J50: August | K50: September | L50: July | M50: August | N50: September | O50: July | P50: August | Q50: September | R50: July | S50: August | T50: September | U50: July | V50: August | W50: September | X50: July | Y50: August | Z50: September | AA50: July | AB50: August | AC50: September | AD50: July | AE50: August | AF50: September | AG50: July | AH50: August | AI50: September | AJ50: July | AK50: August | AL50: September | AM50: July | AN50: August | AO50: September | AP50: July | AQ50: August | AR50: September
C51: Revenue | D51: Revenue | E51: Revenue | F51: Target Revenue | G51: Target Revenue | H51: Target Revenue | I51: Previous Year Revenue | J51: Previous Year Revenue | K51: Previous Year Revenue | L51: Number of Customers | M51: Number of Customers | N51: Number of Customers | O51: Number of New Customers Target | P51: Number of New Customers Target | Q51: Number of New Customers Target | R51: Number of New Customers | S51: Number of New Customers | T51: Number of New Customers | U51: Number of New Customers Previous Year | V51: Number of New Customers Previous Year | W51: Number of New Customers Previous Year | X51: Customer Acquisition Costs | Y51: Customer Acquisition Costs | Z51: Customer Acquisition Costs | AA51: Customer AC (per customer) | AB51: Customer AC (per customer) | AC51: Customer AC (per customer) | AD51: Customer AC (per customer) Target | AE51: Customer AC (per customer) Target | AF51: Customer AC (per customer) Target | AG51: Customer Aquis. Costs (per customer) PY | AH51: Customer Aquis. Costs (per customer) PY | AI51: Customer Aquis. Costs (per customer) PY | AJ51: Revenue per Customer | AK51: Revenue per Customer | AL51: Revenue per Customer | AM51: Revenue per Customer PY | AN51: Revenue per Customer PY | AO51: Revenue per Customer PY | AP51: Target Revenue per Customer | AQ51: Target Revenue per Customer | AR51: Target Revenue per Customer
B52: Jacob | C52: 150000 | D52: 145000 | E52: 145000 | F52: 160000 | G52: 145000 | H52: 160000 | I52: 160000 | J52: 125000 | K52: 145000 | L52: 55 | M52: 55 | N52: 60 | O52: 20 | P52: 25 | Q52: 35 | R52: 14 | S52: 18 | T52: 17 | U52: 21 | V52: 15 | W52: 11 | X52: 8000 | Y52: 6000 | Z52: 4000 | AA52: 571.43 | AB52: 333.33 | AC52: 235.29 | AD52: 350 | AE52: 450 | AF52: 350 | AG52: 400 | AH52: 385 | AI52: 390 | AJ52: 2909.09 | AK52: 2636.36 | AL52: 2416.67 | AM52: 2800 | AN52: 2500 | AO52: 2300 | AP52: 2200 | AQ52: 2300 | AR52: 2500
...

Sheet DASHBOARD
A2: KPI Overview | D2: Q1 2024
A3: Revenue Compared per year | M3: New Customers per year
A5: Revenue Actual VS Target | M5: New Customers Actual VS Target
A7: =SUM(DATA!C16:E16) -> 2346500 | B7: Actual Revenue | M7: =SUM(DATA!R16:T16) -> 307 | P7: Actual New Customers
A9: =SUM(DATA!F16:H16) -> 2200000 | B9: Target | M9: =SUM(DATA!O16:Q16) -> 350 | P9: Target New
A11: =A7/A9 -> 1.0665909 | B11: Target | M11: =M7/M9 -> 0.87714286 | P11: Target
A21: Average Revenue Per Year | M21: Customer Acquisition costs per year
A24: Avg. Revenue per Customer | M24: Customer Acquisition costs
A26: =SUM(DATA!AJ16:AL16)/3 -> 2431.3307 | B26: Actual Revenue per Customer | M26: =SUM(DATA!AA16:AC16)/3 -> 438.46867 | P26: Actual CAC
A28: =SUM(DATA!AP16:AR16)/3 -> 2500 | B28: Target Revenue per | M28: =SUM(DATA!AD16:AF16)/3 -> 350 | P28: Target
A30: =A26/A28 -> 0.97253227 | B30: Target | M30: =M26/M28 -> 1.2527676 | P30: Target
